Workbook

Sheet Year 1
A1: Pork & Garlic Ice Cream Co. — Year 1
A2: Group 7. Blue = you type it. Black = formula. Green = pulled from another sheet. Yellow = fill this in each season.
B4: Winter | C4: Spring | D4: Summer | E4: Autumn | F4: Year 1 total
A5: DECISIONS — what the team chose
A6: Premise rented (A-F) | B6: D
A7: Planned production (units) | B7: 70000
A8: Milk bought (tons) | B8: 3.5
A9: Market investment (Sh) | B9: 5000
A10: Ice creams requested | B10: 70000
A11: Ice creams ALLOCATED by the trainer | B11: 20000
A12: Machines bought this season (Sh cash) | B12: 35000
A13: WHAT THE DECISIONS PRODUCE
A14: Rent | B14: =IFERROR(INDEX(Rules!$D$21:$D$26,MATCH(B6,Rules!$A$21:$A$26,0)),0) -> 17000 | C14: =IFERROR(INDEX(Rules!$D$21:$D$26,MATCH(C6,Rules!$A$21:$A$26,0)),0) -> 0 | D14: =IFERROR(INDEX(Rules!$D$21:$D$26,MATCH(D6,Rules!$A$21:$A$26,0)),0) -> 0 | E14: =IFERROR(INDEX(Rules!$D$21:$D$26,MATCH(E6,Rules!$A$21:$A$26,0)),0) -> 0 | F14: =SUM(B14:E14) -> 17000
A15: Transport rate (Sh per unit sold) | B15: =IFERROR(INDEX(Rules!$C$21:$C$26,MATCH(B6,Rules!$A$21:$A$26,0)),0) -> 0.1 | C15: =IFERROR(INDEX(Rules!$C$21:$C$26,MATCH(C6,Rules!$A$21:$A$26,0)),0) -> 0 | D15: =IFERROR(INDEX(Rules!$C$21:$C$26,MATCH(D6,Rules!$A$21:$A$26,0)),0) -> 0 | E15: =IFERROR(INDEX(Rules!$C$21:$C$26,MATCH(E6,Rules!$A$21:$A$26,0)),0) -> 0
A16: Machine capacity available (units) | B16: =SUMPRODUCT(Machines!H5:H10,Machines!$E$5:$E$10) -> 72000 | C16: =SUMPRODUCT(Machines!I5:I10,Machines!$E$5:$E$10) -> 72000 | D16: =SUMPRODUCT(Machines!J5:J10,Machines!$E$5:$E$10) -> 72000 | E16: =SUMPRODUCT(Machines!K5:K10,Machines!$E$5:$E$10) -> 72000
A17: Ice creams the milk allows | B17: =B8*Rules!$B$8 -> 70000 | C17: =C8*Rules!$B$8 -> 0 | D17: =D8*Rules!$B$8 -> 0 | E17: =E8*Rules!$B$8 -> 0
A18: PRODUCED (lowest of plan, capacity, milk) | B18: =MIN(B7,B16,B17) -> 70000 | C18: =MIN(C7,C16,C17) -> 0 | D18: =MIN(D7,D16,D17) -> 0 | E18: =MIN(E7,E16,E17) -> 0 | F18: =SUM(B18:E18) -> 70000
A19: SOLD (lowest of allocation, request, production) | B19: =MIN(B11,B10,B18) -> 20000 | C19: =MIN(C11,C10,C18) -> 0 | D19: =MIN(D11,D10,D18) -> 0 | E19: =MIN(E11,E10,E18) -> 0 | F19: =SUM(B19:E19) -> 20000
A20: SPOILED — thrown away at season end | B20: =B18-B19 -> 50000 | C20: =C18-C19 -> 0 | D20: =D18-D19 -> 0 | E20: =E18-E19 -> 0 | F20: =SUM(B20:E20) -> 50000
A21: Fill rate (sold / requested) | B21: =IF(B10=0,0,B19/B10) -> 0.28571429 | C21: =IF(C10=0,0,C19/C10) -> 0 | D21: =IF(D10=0,0,D19/D10) -> 0 | E21: =IF(E10=0,0,E19/E10) -> 0
A22: PROFIT & LOSS
A23: Revenue | B23: =ROUND(B19*Rules!$B$6,0) -> 40000 | C23: =ROUND(C19*Rules!$B$6,0) -> 0 | D23: =ROUND(D19*Rules!$B$6,0) -> 0 | E23: =ROUND(E19*Rules!$B$6,0) -> 0 | F23: =SUM(B23:E23) -> 40000
A24: Cost of milk bought (spoiled portion included) | B24: =-ROUND(B8*Rules!$B$7,0) -> -70000 | C24: =-ROUND(C8*Rules!$B$7,0) -> 0 | D24: =-ROUND(D8*Rules!$B$7,0) -> 0 | E24: =-ROUND(E8*Rules!$B$7,0) -> 0 | F24: =SUM(B24:E24) -> -70000
A25: Machine maintenance | B25: =-Machines!L11 -> -1800 | C25: =-Machines!M11 -> -1800 | D25: =-Machines!N11 -> -1800 | E25: =-Machines!O11 -> -1800 | F25: =SUM(B25:E25) -> -7200
A26: Machine depreciation | B26: =-Machines!P11 -> -4375 | C26: =-Machines!Q11 -> -4375 | D26: =-Machines!R11 -> -4375 | E26: =-Machines!S11 -> -4375 | F26: =SUM(B26:E26) -> -17500
A27: GROSS PROFIT | B27: =B23+B24+B25+B26 -> -36175 | C27: =C23+C24+C25+C26 -> -6175 | D27: =D23+D24+D25+D26 -> -6175 | E27: =E23+E24+E25+E26 -> -6175 | F27: =SUM(B27:E27) -> -54700
A28: Transport | B28: =-ROUND(B19*B15,0) -> -2000 | C28: =-ROUND(C19*C15,0) -> 0 | D28: =-ROUND(D19*D15,0) -> 0 | E28: =-ROUND(E19*E15,0) -> 0 | F28: =SUM(B28:E28) -> -2000
A29: Market investment | B29: =-B9 -> -5000 | C29: =-C9 -> 0 | D29: =-D9 -> 0 | E29: =-E9 -> 0 | F29: =SUM(B29:E29) -> -5000
A30: Bonus — 5% of gross profit when positive | B30: =-IF(B27>0,ROUND(B27*Rules!$B$13,0),0) -> 0 | C30: =-IF(C27>0,ROUND(C27*Rules!$B$13,0),0) -> 0 | D30: =-IF(D27>0,ROUND(D27*Rules!$B$13,0),0) -> 0 | E30: =-IF(E27>0,ROUND(E27*Rules!$B$13,0),0) -> 0 | F30: =SUM(B30:E30) -> 0
A31: Fixed salaries | B31: =-Rules!$B$12 -> -10000 | C31: =-Rules!$B$12 -> -10000 | D31: =-Rules!$B$12 -> -10000 | E31: =-Rules!$B$12 -> -10000 | F31: =SUM(B31:E31) -> -40000
A32: Premise rent | B32: =-B14 -> -17000 | C32: =-C14 -> 0 | D32: =-D14 -> 0 | E32: =-E14 -> 0 | F32: =SUM(B32:E32) -> -17000
A33: Loan interest | B33: =-Loans!B34 -> -5000 | C33: =-Loans!C34 -> -4375 | D33: =-Loans!D34 -> -3750 | E33: =-Loans!E34 -> -3125 | F33: =SUM(B33:E33) -> -16250
A34: PROFIT BEFORE TAX | B34: =B27+B28+B29+B30+B31+B32+B33 -> -75175 | C34: =C27+C28+C29+C30+C31+C32+C33 -> -20550 | D34: =D27+D28+D29+D30+D31+D32+D33 -> -19925 | E34: =E27+E28+E29+E30+E31+E32+E33 -> -19300 | F34: =SUM(B34:E34) -> -134950
A35: TAX LOSS POOL
A36: Loss pool brought in | B36: =0 -> 0 | C36: =B40 -> 75175 | D36: =C40 -> 95725 | E36: =D40 -> 115650
A37: Used against this season's profit | B37: =IF(B34>0,MIN(B34,B36),0) -> 0 | C37: =IF(C34>0,MIN(C34,C36),0) -> 0 | D37: =IF(D34>0,MIN(D34,D36),0) -> 0 | E37: =IF(E34>0,MIN(E34,E36),0) -> 0
A38: Taxable profit | B38: =MAX(B34-B37,0) -> 0 | C38: =MAX(C34-C37,0) -> 0 | D38: =MAX(D34-D37,0) -> 0 | E38: =MAX(E34-E37,0) -> 0
A39: Game tax — 10% | B39: =-ROUND(B38*Rules!$B$14,0) -> 0 | C39: =-ROUND(C38*Rules!$B$14,0) -> 0 | D39: =-ROUND(D38*Rules!$B$14,0) -> 0 | E39: =-ROUND(E38*Rules!$B$14,0) -> 0 | F39: =SUM(B39:E39) -> 0
A40: Loss pool carried forward | B40: =B36-B37+IF(B34<0,-B34,0) -> 75175 | C40: =C36-C37+IF(C34<0,-C34,0) -> 95725 | D40: =D36-D37+IF(D34<0,-D34,0) -> 115650 | E40: =E36-E37+IF(E34<0,-E34,0) -> 134950
A41: NET PROFIT FOR THE SEASON | B41: =B34+B39 -> -75175 | C41: =C34+C39 -> -20550 | D41: =D34+D39 -> -19925 | E41: =E34+E39 -> -19300 | F41: =SUM(B41:E41) -> -134950
...

Sheet Rules
A1: Year 1 rules and catalogue
A2: From the participant handout. Blue cells are the numbers the handout gives.
A4: CONSTANTS
A5: Starting cash (once, Year 1 winter) | B5: 100000
A6: Selling price per ice cream | B6: 2
A7: Milk price per ton | B7: 20000
A8: Ice creams per ton of milk | B8: 20000
A9: Minimum milk purchase (tons/season) | B9: 1
A10: Minimum market investment | B10: 1000
A11: Sales request block size | B11: 10000
A12: Fixed salaries per season | B12: 10000
A13: Bonus, % of gross profit when positive | B13: 0.05
A14: Game tax rate | B14: 0.1
A15: Loan interest per season | B15: 0.1
A16: Depreciation life (seasons) | B16: 8
A19: PREMISES
A20: Premise | B20: Machine slots | C20: Transport Sh/sold unit | D20: Rent Sh/season
A21: A | B21: 1 | C21: 0.3 | D21: 12000
A22: B | B22: 1 | C22: 0.4 | D22: 10000
A23: C | B23: 1 | C23: 0.3 | D23: 12000
A24: D | B24: 1 | C24: 0.1 | D24: 17000
A25: E | B25: 2 | C25: 0.2 | D25: 15000
A26: F | B26: 3 | C26: 0.2 | D26: 16000
A29: MACHINES
A30: Machine | B30: Capacity units/season | C30: Purchase Sh | D30: Maintenance Sh/season | E30: Depreciation Sh/season
A31: M1 | B31: 72000 | C31: 35000 | D31: 1800 | E31: 4375
A32: M2 | B32: 120000 | C32: 95000 | D32: 2900 | E32: 11875
A33: M3 | B33: 68000 | C33: 38000 | D33: 2100 | E33: 4750
A34: M4 | B34: 95000 | C34: 70000 | D34: 2900 | E34: 8750
A35: M5 | B35: 45000 | C35: 28000 | D35: 1300 | E35: 3500
A36: M6 | B36: 110000 | C36: 90000 | D36: 2900 | E36: 11250
A38: DEMAND FORECAST (not a promise of sales)
A39: Season | B39: Year 1 | C39: Year 2 | D39: Year 3
A40: Winter | B40: 280000 | C40: 410000 | D40: 540000
A41: Spring | B41: 360000 | C41: 550000 | D41: 750000
A42: Summer | B42: 400000 | C42: 650000 | D42: 900000
A43: Autumn | B43: 320000 | C43: 470000 | D43: 620000

Sheet Machines
A1: Machine register
A2: One row per machine copy owned. Enter the type and the season it was bought (1 = Y1 winter ... 4 = Y1 autumn). Leave the season blank if not owned.
A4: # | B4: Type | C4: Bought in season | D4: Price | E4: Capacity | F4: Maintenance/season | G4: Depreciation/season | H4: Owned in Winter | I4: Owned in Spring | J4: Owned in Summer | K4: Owned in Autumn | L4: Maint Winter | M4: Maint Spring | N4: Maint Summer | O4: Maint Autumn | P4: Depr Winter | Q4: Depr Spring | R4: Depr Summer | S4: Depr Autumn | T4: Seasons left after Winter | U4: Seasons left after Spring | V4: Seasons left after Summer | W4: Seasons left after Autumn
A5: 1 | B5: M1 | C5: 1 | D5: =IFERROR(INDEX(Rules!$C$31:$C$36,MATCH($B5,Rules!$A$31:$A$36,0)),0) -> 35000 | E5: =IFERROR(INDEX(Rules!$B$31:$B$36,MATCH($B5,Rules!$A$31:$A$36,0)),0) -> 72000 | F5: =IFERROR(INDEX(Rules!$D$31:$D$36,MATCH($B5,Rules!$A$31:$A$36,0)),0) -> 1800 | G5: =IFERROR(INDEX(Rules!$E$31:$E$36,MATCH($B5,Rules!$A$31:$A$36,0)),0) -> 4375 | H5: =IF(AND($B5<>"",$C5<>"",$C5<=1),1,0) -> 1 | I5: =IF(AND($B5<>"",$C5<>"",$C5<=2),1,0) -> 1 | J5: =IF(AND($B5<>"",$C5<>"",$C5<=3),1,0) -> 1 | K5: =IF(AND($B5<>"",$C5<>"",$C5<=4),1,0) -> 1 | L5: =H5*$F5 -> 1800 | M5: =I5*$F5 -> 1800 | N5: =J5*$F5 -> 1800 | O5: =K5*$F5 -> 1800 | P5: =IF(AND(H5=1,1-$C5+1<=Rules!$B$16),$G5,0) -> 4375 | Q5: =IF(AND(I5=1,2-$C5+1<=Rules!$B$16),$G5,0) -> 4375 | R5: =IF(AND(J5=1,3-$C5+1<=Rules!$B$16),$G5,0) -> 4375 | S5: =IF(AND(K5=1,4-$C5+1<=Rules!$B$16),$G5,0) -> 4375 | T5: =IF(H5=1,MAX(Rules!$B$16-(1-$C5+1),0),"") -> 7 | U5: =IF(I5=1,MAX(Rules!$B$16-(2-$C5+1),0),"") -> 6 | V5: =IF(J5=1,MAX(Rules!$B$16-(3-$C5+1),0),"") -> 5 | W5: =IF(K5=1,MAX(Rules!$B$16-(4-$C5+1),0),"") -> 4
A6: 2 | D6: =IFERROR(INDEX(Rules!$C$31:$C$36,MATCH($B6,Rules!$A$31:$A$36,0)),0) -> 0 | E6: =IFERROR(INDEX(Rules!$B$31:$B$36,MATCH($B6,Rules!$A$31:$A$36,0)),0) -> 0 | F6: =IFERROR(INDEX(Rules!$D$31:$D$36,MATCH($B6,Rules!$A$31:$A$36,0)),0) -> 0 | G6: =IFERROR(INDEX(Rules!$E$31:$E$36,MATCH($B6,Rules!$A$31:$A$36,0)),0) -> 0 | H6: =IF(AND($B6<>"",$C6<>"",$C6<=1),1,0) -> 0 | I6: =IF(AND($B6<>"",$C6<>"",$C6<=2),1,0) -> 0 | J6: =IF(AND($B6<>"",$C6<>"",$C6<=3),1,0) -> 0 | K6: =IF(AND($B6<>"",$C6<>"",$C6<=4),1,0) -> 0 | L6: =H6*$F6 -> 0 | M6: =I6*$F6 -> 0 | N6: =J6*$F6 -> 0 | O6: =K6*$F6 -> 0 | P6: =IF(AND(H6=1,1-$C6+1<=Rules!$B$16),$G6,0) -> 0 | Q6: =IF(AND(I6=1,2-$C6+1<=Rules!$B$16),$G6,0) -> 0 | R6: =IF(AND(J6=1,3-$C6+1<=Rules!$B$16),$G6,0) -> 0 | S6: =IF(AND(K6=1,4-$C6+1<=Rules!$B$16),$G6,0) -> 0 | T6: =IF(H6=1,MAX(Rules!$B$16-(1-$C6+1),0),"") | U6: =IF(I6=1,MAX(Rules!$B$16-(2-$C6+1),0),"") | V6: =IF(J6=1,MAX(Rules!$B$16-(3-$C6+1),0),"") | W6: =IF(K6=1,MAX(Rules!$B$16-(4-$C6+1),0),"")
A7: 3 | D7: =IFERROR(INDEX(Rules!$C$31:$C$36,MATCH($B7,Rules!$A$31:$A$36,0)),0) -> 0 | E7: =IFERROR(INDEX(Rules!$B$31:$B$36,MATCH($B7,Rules!$A$31:$A$36,0)),0) -> 0 | F7: =IFERROR(INDEX(Rules!$D$31:$D$36,MATCH($B7,Rules!$A$31:$A$36,0)),0) -> 0 | G7: =IFERROR(INDEX(Rules!$E$31:$E$36,MATCH($B7,Rules!$A$31:$A$36,0)),0) -> 0 | H7: =IF(AND($B7<>"",$C7<>"",$C7<=1),1,0) -> 0 | I7: =IF(AND($B7<>"",$C7<>"",$C7<=2),1,0) -> 0 | J7: =IF(AND($B7<>"",$C7<>"",$C7<=3),1,0) -> 0 | K7: =IF(AND($B7<>"",$C7<>"",$C7<=4),1,0) -> 0 | L7: =H7*$F7 -> 0 | M7: =I7*$F7 -> 0 | N7: =J7*$F7 -> 0 | O7: =K7*$F7 -> 0 | P7: =IF(AND(H7=1,1-$C7+1<=Rules!$B$16),$G7,0) -> 0 | Q7: =IF(AND(I7=1,2-$C7+1<=Rules!$B$16),$G7,0) -> 0 | R7: =IF(AND(J7=1,3-$C7+1<=Rules!$B$16),$G7,0) -> 0 | S7: =IF(AND(K7=1,4-$C7+1<=Rules!$B$16),$G7,0) -> 0 | T7: =IF(H7=1,MAX(Rules!$B$16-(1-$C7+1),0),"") | U7: =IF(I7=1,MAX(Rules!$B$16-(2-$C7+1),0),"") | V7: =IF(J7=1,MAX(Rules!$B$16-(3-$C7+1),0),"") | W7: =IF(K7=1,MAX(Rules!$B$16-(4-$C7+1),0),"")
A8: 4 | D8: =IFERROR(INDEX(Rules!$C$31:$C$36,MATCH($B8,Rules!$A$31:$A$36,0)),0) -> 0 | E8: =IFERROR(INDEX(Rules!$B$31:$B$36,MATCH($B8,Rules!$A$31:$A$36,0)),0) -> 0 | F8: =IFERROR(INDEX(Rules!$D$31:$D$36,MATCH($B8,Rules!$A$31:$A$36,0)),0) -> 0 | G8: =IFERROR(INDEX(Rules!$E$31:$E$36,MATCH($B8,Rules!$A$31:$A$36,0)),0) -> 0 | H8: =IF(AND($B8<>"",$C8<>"",$C8<=1),1,0) -> 0 | I8: =IF(AND($B8<>"",$C8<>"",$C8<=2),1,0) -> 0 | J8: =IF(AND($B8<>"",$C8<>"",$C8<=3),1,0) -> 0 | K8: =IF(AND($B8<>"",$C8<>"",$C8<=4),1,0) -> 0 | L8: =H8*$F8 -> 0 | M8: =I8*$F8 -> 0 | N8: =J8*$F8 -> 0 | O8: =K8*$F8 -> 0 | P8: =IF(AND(H8=1,1-$C8+1<=Rules!$B$16),$G8,0) -> 0 | Q8: =IF(AND(I8=1,2-$C8+1<=Rules!$B$16),$G8,0) -> 0 | R8: =IF(AND(J8=1,3-$C8+1<=Rules!$B$16),$G8,0) -> 0 | S8: =IF(AND(K8=1,4-$C8+1<=Rules!$B$16),$G8,0) -> 0 | T8: =IF(H8=1,MAX(Rules!$B$16-(1-$C8+1),0),"") | U8: =IF(I8=1,MAX(Rules!$B$16-(2-$C8+1),0),"") | V8: =IF(J8=1,MAX(Rules!$B$16-(3-$C8+1),0),"") | W8: =IF(K8=1,MAX(Rules!$B$16-(4-$C8+1),0),"")
A9: 5 | D9: =IFERROR(INDEX(Rules!$C$31:$C$36,MATCH($B9,Rules!$A$31:$A$36,0)),0) -> 0 | E9: =IFERROR(INDEX(Rules!$B$31:$B$36,MATCH($B9,Rules!$A$31:$A$36,0)),0) -> 0 | F9: =IFERROR(INDEX(Rules!$D$31:$D$36,MATCH($B9,Rules!$A$31:$A$36,0)),0) -> 0 | G9: =IFERROR(INDEX(Rules!$E$31:$E$36,MATCH($B9,Rules!$A$31:$A$36,0)),0) -> 0 | H9: =IF(AND($B9<>"",$C9<>"",$C9<=1),1,0) -> 0 | I9: =IF(AND($B9<>"",$C9<>"",$C9<=2),1,0) -> 0 | J9: =IF(AND($B9<>"",$C9<>"",$C9<=3),1,0) -> 0 | K9: =IF(AND($B9<>"",$C9<>"",$C9<=4),1,0) -> 0 | L9: =H9*$F9 -> 0 | M9: =I9*$F9 -> 0 | N9: =J9*$F9 -> 0 | O9: =K9*$F9 -> 0 | P9: =IF(AND(H9=1,1-$C9+1<=Rules!$B$16),$G9,0) -> 0 | Q9: =IF(AND(I9=1,2-$C9+1<=Rules!$B$16),$G9,0) -> 0 | R9: =IF(AND(J9=1,3-$C9+1<=Rules!$B$16),$G9,0) -> 0 | S9: =IF(AND(K9=1,4-$C9+1<=Rules!$B$16),$G9,0) -> 0 | T9: =IF(H9=1,MAX(Rules!$B$16-(1-$C9+1),0),"") | U9: =IF(I9=1,MAX(Rules!$B$16-(2-$C9+1),0),"") | V9: =IF(J9=1,MAX(Rules!$B$16-(3-$C9+1),0),"") | W9: =IF(K9=1,MAX(Rules!$B$16-(4-$C9+1),0),"")
A10: 6 | D10: =IFERROR(INDEX(Rules!$C$31:$C$36,MATCH($B10,Rules!$A$31:$A$36,0)),0) -> 0 | E10: =IFERROR(INDEX(Rules!$B$31:$B$36,MATCH($B10,Rules!$A$31:$A$36,0)),0) -> 0 | F10: =IFERROR(INDEX(Rules!$D$31:$D$36,MATCH($B10,Rules!$A$31:$A$36,0)),0) -> 0 | G10: =IFERROR(INDEX(Rules!$E$31:$E$36,MATCH($B10,Rules!$A$31:$A$36,0)),0) -> 0 | H10: =IF(AND($B10<>"",$C10<>"",$C10<=1),1,0) -> 0 | I10: =IF(AND($B10<>"",$C10<>"",$C10<=2),1,0) -> 0 | J10: =IF(AND($B10<>"",$C10<>"",$C10<=3),1,0) -> 0 | K10: =IF(AND($B10<>"",$C10<>"",$C10<=4),1,0) -> 0 | L10: =H10*$F10 -> 0 | M10: =I10*$F10 -> 0 | N10: =J10*$F10 -> 0 | O10: =K10*$F10 -> 0 | P10: =IF(AND(H10=1,1-$C10+1<=Rules!$B$16),$G10,0) -> 0 | Q10: =IF(AND(I10=1,2-$C10+1<=Rules!$B$16),$G10,0) -> 0 | R10: =IF(AND(J10=1,3-$C10+1<=Rules!$B$16),$G10,0) -> 0 | S10: =IF(AND(K10=1,4-$C10+1<=Rules!$B$16),$G10,0) -> 0 | T10: =IF(H10=1,MAX(Rules!$B$16-(1-$C10+1),0),"") | U10: =IF(I10=1,MAX(Rules!$B$16-(2-$C10+1),0),"") | V10: =IF(J10=1,MAX(Rules!$B$16-(3-$C10+1),0),"") | W10: =IF(K10=1,MAX(Rules!$B$16-(4-$C10+1),0),"")
A11: Total | L11: =SUM(L5:L10) -> 1800 | M11: =SUM(M5:M10) -> 1800 | N11: =SUM(N5:N10) -> 1800 | O11: =SUM(O5:O10) -> 1800 | P11: =SUM(P5:P10) -> 4375 | Q11: =SUM(Q5:Q10) -> 4375 | R11: =SUM(R5:R10) -> 4375 | S11: =SUM(S5:S10) -> 4375
A13: Group 7 owns one Machine 1, bought in Year 1 winter.

Sheet Loans
A1: Loan register
A2: Equal principal each season; interest is 10% of the debt standing immediately before that season's repayment; first payment falls in the season of borrowing.
A4: Loan 1
A5: Amount | B5: 50000 | C5: Term (seasons) | D5: 8 | E5: Taken in season | F5: 1
B6: Winter | C6: Spring | D6: Summer | E6: Autumn
A7: Debt before repayment | B7: =IF($B$5="",0,IF($F$5=1,$B$5,0)) -> 50000 | C7: =IF($B$5="",0,IF($F$5=2,$B$5,B11)) -> 43750 | D7: =IF($B$5="",0,IF($F$5=3,$B$5,C11)) -> 37500 | E7: =IF($B$5="",0,IF($F$5=4,$B$5,D11)) -> 31250
A8: Interest | B8: =ROUND(B7*Rules!$B$15,0) -> 5000 | C8: =ROUND(C7*Rules!$B$15,0) -> 4375 | D8: =ROUND(D7*Rules!$B$15,0) -> 3750 | E8: =ROUND(E7*Rules!$B$15,0) -> 3125
A9: Principal | B9: =IF(OR($B$5="",$D$5="",B7=0),0,MIN(ROUND($B$5/$D$5,0),B7)) -> 6250 | C9: =IF(OR($B$5="",$D$5="",C7=0),0,MIN(ROUND($B$5/$D$5,0),C7)) -> 6250 | D9: =IF(OR($B$5="",$D$5="",D7=0),0,MIN(ROUND($B$5/$D$5,0),D7)) -> 6250 | E9: =IF(OR($B$5="",$D$5="",E7=0),0,MIN(ROUND($B$5/$D$5,0),E7)) -> 6250
A10: Bank payment | B10: =B8+B9 -> 11250 | C10: =C8+C9 -> 10625 | D10: =D8+D9 -> 10000 | E10: =E8+E9 -> 9375
A11: Debt after | B11: =B7-B9 -> 43750 | C11: =C7-C9 -> 37500 | D11: =D7-D9 -> 31250 | E11: =E7-E9 -> 25000
A14: Loan 2
A15: Amount | C15: Term (seasons) | E15: Taken in season
B16: Winter | C16: Spring | D16: Summer | E16: Autumn
A17: Debt before repayment | B17: =IF($B$15="",0,IF($F$15=1,$B$15,0)) -> 0 | C17: =IF($B$15="",0,IF($F$15=2,$B$15,B21)) -> 0 | D17: =IF($B$15="",0,IF($F$15=3,$B$15,C21)) -> 0 | E17: =IF($B$15="",0,IF($F$15=4,$B$15,D21)) -> 0
A18: Interest | B18: =ROUND(B17*Rules!$B$15,0) -> 0 | C18: =ROUND(C17*Rules!$B$15,0) -> 0 | D18: =ROUND(D17*Rules!$B$15,0) -> 0 | E18: =ROUND(E17*Rules!$B$15,0) -> 0
A19: Principal | B19: =IF(OR($B$15="",$D$15="",B17=0),0,MIN(ROUND($B$15/$D$15,0),B17)) -> 0 | C19: =IF(OR($B$15="",$D$15="",C17=0),0,MIN(ROUND($B$15/$D$15,0),C17)) -> 0 | D19: =IF(OR($B$15="",$D$15="",D17=0),0,MIN(ROUND($B$15/$D$15,0),D17)) -> 0 | E19: =IF(OR($B$15="",$D$15="",E17=0),0,MIN(ROUND($B$15/$D$15,0),E17)) -> 0
A20: Bank payment | B20: =B18+B19 -> 0 | C20: =C18+C19 -> 0 | D20: =D18+D19 -> 0 | E20: =E18+E19 -> 0
A21: Debt after | B21: =B17-B19 -> 0 | C21: =C17-C19 -> 0 | D21: =D17-D19 -> 0 | E21: =E17-E19 -> 0
A24: Loan 3
A25: Amount | C25: Term (seasons) | E25: Taken in season
B26: Winter | C26: Spring | D26: Summer | E26: Autumn
A27: Debt before repayment | B27: =IF($B$25="",0,IF($F$25=1,$B$25,0)) -> 0 | C27: =IF($B$25="",0,IF($F$25=2,$B$25,B31)) -> 0 | D27: =IF($B$25="",0,IF($F$25=3,$B$25,C31)) -> 0 | E27: =IF($B$25="",0,IF($F$25=4,$B$25,D31)) -> 0
A28: Interest | B28: =ROUND(B27*Rules!$B$15,0) -> 0 | C28: =ROUND(C27*Rules!$B$15,0) -> 0 | D28: =ROUND(D27*Rules!$B$15,0) -> 0 | E28: =ROUND(E27*Rules!$B$15,0) -> 0
A29: Principal | B29: =IF(OR($B$25="",$D$25="",B27=0),0,MIN(ROUND($B$25/$D$25,0),B27)) -> 0 | C29: =IF(OR($B$25="",$D$25="",C27=0),0,MIN(ROUND($B$25/$D$25,0),C27)) -> 0 | D29: =IF(OR($B$25="",$D$25="",D27=0),0,MIN(ROUND($B$25/$D$25,0),D27)) -> 0 | E29: =IF(OR($B$25="",$D$25="",E27=0),0,MIN(ROUND($B$25/$D$25,0),E27)) -> 0
A30: Bank payment | B30: =B28+B29 -> 0 | C30: =C28+C29 -> 0 | D30: =D28+D29 -> 0 | E30: =E28+E29 -> 0
A31: Debt after | B31: =B27-B29 -> 0 | C31: =C27-C29 -> 0 | D31: =D27-D29 -> 0 | E31: =E27-E29 -> 0
A34: TOTAL interest (to the P&L) | B34: =B8+B18+B28 -> 5000 | C34: =C8+C18+C28 -> 4375 | D34: =D8+D18+D28 -> 3750 | E34: =E8+E18+E28 -> 3125
A35: TOTAL bank payment (cash only) | B35: =B10+B20+B30 -> 11250 | C35: =C10+C20+C30 -> 10625 | D35: =D10+D20+D30 -> 10000 | E35: =E10+E20+E30 -> 9375
A36: TOTAL principal (cash only) | B36: =B35-B34 -> 6250 | C36: =C35-C34 -> 6250 | D36: =D35-D34 -> 6250 | E36: =E35-E34 -> 6250
A38: Group 7 borrowed Sh 50,000 in Year 1 winter. TERM IS THE TEAM'S OWN CHOICE (1-8 seasons) - check your decision record.
